17-04-11 13:59:39 ERROR (MainThread) [homeassistant.core] Timer got out of sync. Resetting
17-04-11 13:59:44 ERROR (MainThread) [homeassistant.core] Error doing job: Task exception was never retrieved
Traceback (most recent call last):
  File "/usr/lib/python3.5/asyncio/tasks.py", line 241, in _step
    result = coro.throw(exc)
  File "/srv/homeassistant/lib/python3.5/site-packages/homeassistant/components/discovery.py", line 110, in scan_devices
    None, _discover, netdisco)
  File "/usr/lib/python3.5/asyncio/futures.py", line 361, in __iter__
    yield self  # This tells Task to wait for completion.
  File "/usr/lib/python3.5/asyncio/tasks.py", line 296, in _wakeup
    future.result()
  File "/usr/lib/python3.5/asyncio/futures.py", line 274, in result
    raise self._exception
  File "/usr/lib/python3.5/concurrent/futures/thread.py", line 55, in run
    result = self.fn(*self.args, **self.kwargs)
  File "/srv/homeassistant/lib/python3.5/site-packages/homeassistant/components/discovery.py", line 127, in _discover
    netdisco.scan()
  File "/home/homeassistant/.homeassistant/deps/netdisco/discovery.py", line 62, in scan
    self.gdm.scan()
  File "/home/homeassistant/.homeassistant/deps/netdisco/gdm.py", line 21, in scan
    self.update()
  File "/home/homeassistant/.homeassistant/deps/netdisco/gdm.py", line 76, in update
    sock.sendto(gdm_msg, (gdm_ip, gdm_port))
OSError: [Errno 101] Network is unreachable
